2018-04-22T10:06:00.229+0000 I CONTROL  [initandlisten] MongoDB starting : pid=8 port=27017 dbpath=/data/db 64-bit host=bd9ee1593ad1
2018-04-22T10:06:00.230+0000 I CONTROL  [initandlisten] db version v3.4.13
2018-04-22T10:06:00.230+0000 I CONTROL  [initandlisten] git version: fbdef2ccc53e0fcc9afb570063633d992b2aae42
2018-04-22T10:06:00.230+0000 I CONTROL  [initandlisten] OpenSSL version: OpenSSL 1.0.1t  3 May 2016
2018-04-22T10:06:00.230+0000 I CONTROL  [initandlisten] allocator: tcmalloc
2018-04-22T10:06:00.230+0000 I CONTROL  [initandlisten] modules: none
2018-04-22T10:06:00.231+0000 I CONTROL  [initandlisten] build environment:
2018-04-22T10:06:00.231+0000 I CONTROL  [initandlisten]     distmod: debian81
2018-04-22T10:06:00.231+0000 I CONTROL  [initandlisten]     distarch: x86_64
2018-04-22T10:06:00.231+0000 I CONTROL  [initandlisten]     target_arch: x86_64
2018-04-22T10:06:00.231+0000 I CONTROL  [initandlisten] options: { security: { authorization: "enabled" }, systemLog: { destination: "file", path: "/logs/mongodb.log" } }
2018-04-22T10:06:00.233+0000 W -        [initandlisten] Detected unclean shutdown - /data/db/mongod.lock is not empty.
2018-04-22T10:06:00.239+0000 I -        [initandlisten] Detected data files in /data/db created by the 'wiredTiger' storage engine, so setting the active storage engine to 'wiredTiger'.
2018-04-22T10:06:00.241+0000 W STORAGE  [initandlisten] Recovering data from the last clean checkpoint.
2018-04-22T10:06:00.242+0000 I STORAGE  [initandlisten] wiredtiger_open config: create,cache_size=487M,session_max=20000,eviction=(threads_min=4,threads_max=4),config_base=false,statistics=(fast),log=(enabled=true,archive=true,path=journal,compressor=snappy),file_manager=(close_idle_time=100000),checkpoint=(wait=60,log_size=2GB),statistics_log=(wait=0),verbose=(recovery_progress),
2018-04-22T10:06:00.996+0000 I STORAGE  [initandlisten] WiredTiger message [1524391560:996212][8:0x7ffff7feed40], txn-recover: Main recovery loop: starting at 7/2816
2018-04-22T10:06:01.016+0000 I STORAGE  [initandlisten] WiredTiger message [1524391561:16004][8:0x7ffff7feed40], txn-recover: Recovering log 7 through 8
2018-04-22T10:06:01.342+0000 I STORAGE  [initandlisten] WiredTiger message [1524391561:342393][8:0x7ffff7feed40], file:sizeStorer.wt, txn-recover: Recovering log 8 through 8
2018-04-22T10:06:01.425+0000 I CONTROL  [initandlisten] ** WARNING: You are running this process as the root user, which is not recommended.
2018-04-22T10:06:01.425+0000 I CONTROL  [initandlisten] 
2018-04-22T10:06:01.432+0000 I FTDC     [initandlisten] Initializing full-time diagnostic data capture with directory '/data/db/diagnostic.data'
2018-04-22T10:06:01.433+0000 I NETWORK  [thread1] waiting for connections on port 27017
2018-04-22T10:06:02.012+0000 I FTDC     [ftdc] Unclean full-time diagnostic data capture shutdown detected, found interim file, some metrics may have been lost. OK
2018-04-22T10:06:03.459+0000 I NETWORK  [thread1] connection accepted from 172.18.1.4:46870 #1 (1 connection now open)
2018-04-22T10:06:03.460+0000 I NETWORK  [conn1] received client metadata from 172.18.1.4:46870 conn1: { driver: { name: "PyMongo", version: "3.6.1" }, os: { type: "Linux", name: "debian 8.10", architecture: "x86_64", version: "4.9.60-linuxkit-aufs" }, platform: "CPython 2.7.14.final.0" }
2018-04-22T10:06:03.461+0000 I NETWORK  [thread1] connection accepted from 172.18.1.4:46872 #2 (2 connections now open)
2018-04-22T10:06:03.462+0000 I NETWORK  [conn2] received client metadata from 172.18.1.4:46872 conn2: { driver: { name: "PyMongo", version: "3.6.1" }, os: { type: "Linux", name: "debian 8.10", architecture: "x86_64", version: "4.9.60-linuxkit-aufs" }, platform: "CPython 2.7.14.final.0" }
2018-04-22T10:06:03.471+0000 I ACCESS   [conn2] Successfully authenticated as principal penework on penework
2018-04-22T10:06:03.496+0000 I NETWORK  [thread1] connection accepted from 172.18.1.4:46874 #3 (3 connections now open)
2018-04-22T10:06:03.496+0000 I NETWORK  [conn3] received client metadata from 172.18.1.4:46874 conn3: { driver: { name: "PyMongo", version: "3.6.1" }, os: { type: "Linux", name: "debian 8.10", architecture: "x86_64", version: "4.9.60-linuxkit-aufs" }, platform: "CPython 2.7.14.final.0" }
2018-04-22T10:06:09.357+0000 I NETWORK  [thread1] connection accepted from 172.18.1.1:40968 #4 (4 connections now open)
2018-04-22T10:06:09.358+0000 I NETWORK  [conn4] received client metadata from 172.18.1.1:40968 conn4: { driver: { name: "PyMongo", version: "3.6.1" }, os: { type: "Darwin", name: "Darwin", architecture: "x86_64", version: "10.13.3" }, platform: "CPython 2.7.14.final.0" }
2018-04-22T10:06:09.371+0000 I NETWORK  [thread1] connection accepted from 172.18.1.1:40970 #5 (5 connections now open)
2018-04-22T10:06:09.372+0000 I NETWORK  [conn5] received client metadata from 172.18.1.1:40970 conn5: { driver: { name: "PyMongo", version: "3.6.1" }, os: { type: "Darwin", name: "Darwin", architecture: "x86_64", version: "10.13.3" }, platform: "CPython 2.7.14.final.0" }
2018-04-22T10:06:09.512+0000 I NETWORK  [thread1] connection accepted from 172.18.1.1:40972 #6 (6 connections now open)
2018-04-22T10:06:09.514+0000 I NETWORK  [conn6] received client metadata from 172.18.1.1:40972 conn6: { driver: { name: "PyMongo", version: "3.6.1" }, os: { type: "Darwin", name: "Darwin", architecture: "x86_64", version: "10.13.3" }, platform: "CPython 2.7.14.final.0" }
2018-04-22T10:06:09.652+0000 I NETWORK  [thread1] connection accepted from 172.18.1.1:40974 #7 (7 connections now open)
2018-04-22T10:06:09.653+0000 I NETWORK  [conn7] received client metadata from 172.18.1.1:40974 conn7: { driver: { name: "PyMongo", version: "3.6.1" }, os: { type: "Darwin", name: "Darwin", architecture: "x86_64", version: "10.13.3" }, platform: "CPython 2.7.14.final.0" }
2018-04-22T10:06:09.735+0000 I NETWORK  [thread1] connection accepted from 172.18.1.1:40976 #8 (8 connections now open)
2018-04-22T10:06:09.736+0000 I NETWORK  [conn8] received client metadata from 172.18.1.1:40976 conn8: { driver: { name: "PyMongo", version: "3.6.1" }, os: { type: "Darwin", name: "Darwin", architecture: "x86_64", version: "10.13.3" }, platform: "CPython 2.7.14.final.0" }
2018-04-22T10:06:09.777+0000 I NETWORK  [thread1] connection accepted from 172.18.1.1:40978 #9 (9 connections now open)
2018-04-22T10:06:09.778+0000 I NETWORK  [conn9] received client metadata from 172.18.1.1:40978 conn9: { driver: { name: "PyMongo", version: "3.6.1" }, os: { type: "Darwin", name: "Darwin", architecture: "x86_64", version: "10.13.3" }, platform: "CPython 2.7.14.final.0" }
2018-04-22T10:06:18.850+0000 I NETWORK  [thread1] connection accepted from 172.18.1.4:46902 #10 (10 connections now open)
2018-04-22T10:06:18.850+0000 I NETWORK  [conn10] received client metadata from 172.18.1.4:46902 conn10: { driver: { name: "PyMongo", version: "3.6.1" }, os: { type: "Linux", name: "debian 8.10", architecture: "x86_64", version: "4.9.60-linuxkit-aufs" }, platform: "CPython 2.7.14.final.0" }
2018-04-22T10:06:18.858+0000 I ACCESS   [conn10] Successfully authenticated as principal penework on penework
2018-04-22T10:06:19.150+0000 I NETWORK  [thread1] connection accepted from 172.18.1.4:46904 #11 (11 connections now open)
2018-04-22T10:06:19.150+0000 I NETWORK  [conn11] received client metadata from 172.18.1.4:46904 conn11: { driver: { name: "PyMongo", version: "3.6.1" }, os: { type: "Linux", name: "debian 8.10", architecture: "x86_64", version: "4.9.60-linuxkit-aufs" }, platform: "CPython 2.7.14.final.0" }
2018-04-22T10:06:19.158+0000 I ACCESS   [conn11] Successfully authenticated as principal penework on penework
2018-04-22T10:07:44.231+0000 I -        [conn10] end connection 172.18.1.4:46902 (11 connections now open)
2018-04-22T10:07:44.231+0000 I -        [conn11] end connection 172.18.1.4:46904 (11 connections now open)
2018-04-22T10:07:44.316+0000 I -        [conn2] end connection 172.18.1.4:46872 (9 connections now open)
2018-04-22T10:07:44.316+0000 I -        [conn3] end connection 172.18.1.4:46874 (9 connections now open)
2018-04-22T10:07:44.316+0000 I -        [conn1] end connection 172.18.1.4:46870 (9 connections now open)
