2018-04-22T09:59:58.503+0000 I CONTROL  [initandlisten] MongoDB starting : pid=8 port=27017 dbpath=/data/db 64-bit host=3e99d92220d0
2018-04-22T09:59:58.503+0000 I CONTROL  [initandlisten] db version v3.4.13
2018-04-22T09:59:58.503+0000 I CONTROL  [initandlisten] git version: fbdef2ccc53e0fcc9afb570063633d992b2aae42
2018-04-22T09:59:58.504+0000 I CONTROL  [initandlisten] OpenSSL version: OpenSSL 1.0.1t  3 May 2016
2018-04-22T09:59:58.504+0000 I CONTROL  [initandlisten] allocator: tcmalloc
2018-04-22T09:59:58.504+0000 I CONTROL  [initandlisten] modules: none
2018-04-22T09:59:58.505+0000 I CONTROL  [initandlisten] build environment:
2018-04-22T09:59:58.505+0000 I CONTROL  [initandlisten]     distmod: debian81
2018-04-22T09:59:58.505+0000 I CONTROL  [initandlisten]     distarch: x86_64
2018-04-22T09:59:58.506+0000 I CONTROL  [initandlisten]     target_arch: x86_64
2018-04-22T09:59:58.506+0000 I CONTROL  [initandlisten] options: { security: { authorization: "enabled" }, systemLog: { destination: "file", path: "/logs/mongodb.log" } }
2018-04-22T09:59:58.508+0000 W -        [initandlisten] Detected unclean shutdown - /data/db/mongod.lock is not empty.
2018-04-22T09:59:58.513+0000 I -        [initandlisten] Detected data files in /data/db created by the 'wiredTiger' storage engine, so setting the active storage engine to 'wiredTiger'.
2018-04-22T09:59:58.514+0000 W STORAGE  [initandlisten] Recovering data from the last clean checkpoint.
2018-04-22T09:59:58.515+0000 I STORAGE  [initandlisten] wiredtiger_open config: create,cache_size=487M,session_max=20000,eviction=(threads_min=4,threads_max=4),config_base=false,statistics=(fast),log=(enabled=true,archive=true,path=journal,compressor=snappy),file_manager=(close_idle_time=100000),checkpoint=(wait=60,log_size=2GB),statistics_log=(wait=0),verbose=(recovery_progress),
2018-04-22T09:59:59.218+0000 I STORAGE  [initandlisten] WiredTiger message [1524391199:218570][8:0x7ffff7feed40], txn-recover: Main recovery loop: starting at 5/2816
2018-04-22T09:59:59.239+0000 I STORAGE  [initandlisten] WiredTiger message [1524391199:239841][8:0x7ffff7feed40], txn-recover: Recovering log 5 through 6
2018-04-22T09:59:59.539+0000 I STORAGE  [initandlisten] WiredTiger message [1524391199:539862][8:0x7ffff7feed40], file:sizeStorer.wt, txn-recover: Recovering log 6 through 6
2018-04-22T09:59:59.628+0000 I CONTROL  [initandlisten] ** WARNING: You are running this process as the root user, which is not recommended.
2018-04-22T09:59:59.628+0000 I CONTROL  [initandlisten] 
2018-04-22T09:59:59.636+0000 I FTDC     [initandlisten] Initializing full-time diagnostic data capture with directory '/data/db/diagnostic.data'
2018-04-22T09:59:59.637+0000 I NETWORK  [thread1] waiting for connections on port 27017
2018-04-22T10:00:00.013+0000 I FTDC     [ftdc] Unclean full-time diagnostic data capture shutdown detected, found interim file, some metrics may have been lost. OK
2018-04-22T10:00:03.135+0000 I NETWORK  [thread1] connection accepted from 172.18.1.4:46782 #1 (1 connection now open)
2018-04-22T10:00:03.136+0000 I NETWORK  [conn1] received client metadata from 172.18.1.4:46782 conn1: { driver: { name: "PyMongo", version: "3.6.1" }, os: { type: "Linux", name: "debian 8.10", architecture: "x86_64", version: "4.9.60-linuxkit-aufs" }, platform: "CPython 2.7.14.final.0" }
2018-04-22T10:00:03.137+0000 I NETWORK  [thread1] connection accepted from 172.18.1.4:46784 #2 (2 connections now open)
2018-04-22T10:00:03.138+0000 I NETWORK  [conn2] received client metadata from 172.18.1.4:46784 conn2: { driver: { name: "PyMongo", version: "3.6.1" }, os: { type: "Linux", name: "debian 8.10", architecture: "x86_64", version: "4.9.60-linuxkit-aufs" }, platform: "CPython 2.7.14.final.0" }
2018-04-22T10:00:03.150+0000 I ACCESS   [conn2] Successfully authenticated as principal penework on penework
2018-04-22T10:00:03.177+0000 I NETWORK  [thread1] connection accepted from 172.18.1.4:46786 #3 (3 connections now open)
2018-04-22T10:00:03.178+0000 I NETWORK  [conn3] received client metadata from 172.18.1.4:46786 conn3: { driver: { name: "PyMongo", version: "3.6.1" }, os: { type: "Linux", name: "debian 8.10", architecture: "x86_64", version: "4.9.60-linuxkit-aufs" }, platform: "CPython 2.7.14.final.0" }
2018-04-22T10:00:06.787+0000 I NETWORK  [thread1] connection accepted from 172.18.1.1:40880 #4 (4 connections now open)
2018-04-22T10:00:06.789+0000 I NETWORK  [conn4] received client metadata from 172.18.1.1:40880 conn4: { driver: { name: "PyMongo", version: "3.6.1" }, os: { type: "Darwin", name: "Darwin", architecture: "x86_64", version: "10.13.3" }, platform: "CPython 2.7.14.final.0" }
2018-04-22T10:00:06.839+0000 I NETWORK  [thread1] connection accepted from 172.18.1.1:40882 #5 (5 connections now open)
2018-04-22T10:00:06.840+0000 I NETWORK  [conn5] received client metadata from 172.18.1.1:40882 conn5: { driver: { name: "PyMongo", version: "3.6.1" }, os: { type: "Darwin", name: "Darwin", architecture: "x86_64", version: "10.13.3" }, platform: "CPython 2.7.14.final.0" }
2018-04-22T10:00:06.933+0000 I NETWORK  [thread1] connection accepted from 172.18.1.1:40884 #6 (6 connections now open)
2018-04-22T10:00:06.934+0000 I NETWORK  [conn6] received client metadata from 172.18.1.1:40884 conn6: { driver: { name: "PyMongo", version: "3.6.1" }, os: { type: "Darwin", name: "Darwin", architecture: "x86_64", version: "10.13.3" }, platform: "CPython 2.7.14.final.0" }
2018-04-22T10:00:07.059+0000 I NETWORK  [thread1] connection accepted from 172.18.1.1:40886 #7 (7 connections now open)
2018-04-22T10:00:07.061+0000 I NETWORK  [conn7] received client metadata from 172.18.1.1:40886 conn7: { driver: { name: "PyMongo", version: "3.6.1" }, os: { type: "Darwin", name: "Darwin", architecture: "x86_64", version: "10.13.3" }, platform: "CPython 2.7.14.final.0" }
2018-04-22T10:00:07.133+0000 I NETWORK  [thread1] connection accepted from 172.18.1.1:40888 #8 (8 connections now open)
2018-04-22T10:00:07.134+0000 I NETWORK  [thread1] connection accepted from 172.18.1.1:40890 #9 (9 connections now open)
2018-04-22T10:00:07.135+0000 I NETWORK  [conn8] received client metadata from 172.18.1.1:40888 conn8: { driver: { name: "PyMongo", version: "3.6.1" }, os: { type: "Darwin", name: "Darwin", architecture: "x86_64", version: "10.13.3" }, platform: "CPython 2.7.14.final.0" }
2018-04-22T10:00:07.135+0000 I NETWORK  [conn9] received client metadata from 172.18.1.1:40890 conn9: { driver: { name: "PyMongo", version: "3.6.1" }, os: { type: "Darwin", name: "Darwin", architecture: "x86_64", version: "10.13.3" }, platform: "CPython 2.7.14.final.0" }
2018-04-22T10:00:08.996+0000 I NETWORK  [thread1] connection accepted from 172.18.1.4:46814 #10 (10 connections now open)
2018-04-22T10:00:08.997+0000 I NETWORK  [conn10] received client metadata from 172.18.1.4:46814 conn10: { driver: { name: "PyMongo", version: "3.6.1" }, os: { type: "Linux", name: "debian 8.10", architecture: "x86_64", version: "4.9.60-linuxkit-aufs" }, platform: "CPython 2.7.14.final.0" }
2018-04-22T10:00:09.008+0000 I ACCESS   [conn10] Successfully authenticated as principal penework on penework
2018-04-22T10:00:09.297+0000 I NETWORK  [thread1] connection accepted from 172.18.1.4:46816 #11 (11 connections now open)
2018-04-22T10:00:09.298+0000 I NETWORK  [conn11] received client metadata from 172.18.1.4:46816 conn11: { driver: { name: "PyMongo", version: "3.6.1" }, os: { type: "Linux", name: "debian 8.10", architecture: "x86_64", version: "4.9.60-linuxkit-aufs" }, platform: "CPython 2.7.14.final.0" }
2018-04-22T10:00:09.306+0000 I ACCESS   [conn11] Successfully authenticated as principal penework on penework
