2018-05-07T14:12:56.589+0000 I CONTROL  [initandlisten] MongoDB starting : pid=8 port=27017 dbpath=/data/db 64-bit host=720fdf3afb72
2018-05-07T14:12:56.589+0000 I CONTROL  [initandlisten] db version v3.4.13
2018-05-07T14:12:56.589+0000 I CONTROL  [initandlisten] git version: fbdef2ccc53e0fcc9afb570063633d992b2aae42
2018-05-07T14:12:56.590+0000 I CONTROL  [initandlisten] OpenSSL version: OpenSSL 1.0.1t  3 May 2016
2018-05-07T14:12:56.591+0000 I CONTROL  [initandlisten] allocator: tcmalloc
2018-05-07T14:12:56.591+0000 I CONTROL  [initandlisten] modules: none
2018-05-07T14:12:56.591+0000 I CONTROL  [initandlisten] build environment:
2018-05-07T14:12:56.591+0000 I CONTROL  [initandlisten]     distmod: debian81
2018-05-07T14:12:56.592+0000 I CONTROL  [initandlisten]     distarch: x86_64
2018-05-07T14:12:56.592+0000 I CONTROL  [initandlisten]     target_arch: x86_64
2018-05-07T14:12:56.592+0000 I CONTROL  [initandlisten] options: { security: { authorization: "enabled" }, systemLog: { destination: "file", path: "/logs/mongodb.log" } }
2018-05-07T14:12:56.593+0000 W -        [initandlisten] Detected unclean shutdown - /data/db/mongod.lock is not empty.
2018-05-07T14:12:56.599+0000 I -        [initandlisten] Detected data files in /data/db created by the 'wiredTiger' storage engine, so setting the active storage engine to 'wiredTiger'.
2018-05-07T14:12:56.601+0000 W STORAGE  [initandlisten] Recovering data from the last clean checkpoint.
2018-05-07T14:12:56.602+0000 I STORAGE  [initandlisten] wiredtiger_open config: create,cache_size=487M,session_max=20000,eviction=(threads_min=4,threads_max=4),config_base=false,statistics=(fast),log=(enabled=true,archive=true,path=journal,compressor=snappy),file_manager=(close_idle_time=100000),checkpoint=(wait=60,log_size=2GB),statistics_log=(wait=0),verbose=(recovery_progress),
2018-05-07T14:12:57.345+0000 I STORAGE  [initandlisten] WiredTiger message [1525702377:345024][8:0x7ffff7feed40], txn-recover: Main recovery loop: starting at 11/92160
2018-05-07T14:12:57.366+0000 I STORAGE  [initandlisten] WiredTiger message [1525702377:366827][8:0x7ffff7feed40], txn-recover: Recovering log 11 through 12
2018-05-07T14:12:57.688+0000 I STORAGE  [initandlisten] WiredTiger message [1525702377:688884][8:0x7ffff7feed40], file:sizeStorer.wt, txn-recover: Recovering log 12 through 12
2018-05-07T14:12:57.785+0000 I CONTROL  [initandlisten] ** WARNING: You are running this process as the root user, which is not recommended.
2018-05-07T14:12:57.785+0000 I CONTROL  [initandlisten] 
2018-05-07T14:12:57.795+0000 I FTDC     [initandlisten] Initializing full-time diagnostic data capture with directory '/data/db/diagnostic.data'
2018-05-07T14:12:57.796+0000 I NETWORK  [thread1] waiting for connections on port 27017
2018-05-07T14:12:58.013+0000 I FTDC     [ftdc] Unclean full-time diagnostic data capture shutdown detected, found interim file, some metrics may have been lost. OK
2018-05-07T14:12:59.684+0000 I NETWORK  [thread1] connection accepted from 172.18.1.1:58708 #1 (1 connection now open)
2018-05-07T14:12:59.685+0000 I NETWORK  [conn1] received client metadata from 172.18.1.1:58708 conn1: { driver: { name: "PyMongo", version: "3.6.1" }, os: { type: "Linux", name: "debian 8.10", architecture: "x86_64", version: "4.9.60-linuxkit-aufs" }, platform: "CPython 2.7.14.final.0" }
2018-05-07T14:12:59.688+0000 I NETWORK  [thread1] connection accepted from 172.18.1.1:58712 #2 (2 connections now open)
2018-05-07T14:12:59.688+0000 I NETWORK  [conn2] received client metadata from 172.18.1.1:58712 conn2: { driver: { name: "PyMongo", version: "3.6.1" }, os: { type: "Linux", name: "debian 8.10", architecture: "x86_64", version: "4.9.60-linuxkit-aufs" }, platform: "CPython 2.7.14.final.0" }
2018-05-07T14:12:59.700+0000 I ACCESS   [conn2] Successfully authenticated as principal penework on penework
2018-05-07T14:12:59.732+0000 I NETWORK  [thread1] connection accepted from 172.18.1.1:58716 #3 (3 connections now open)
2018-05-07T14:12:59.733+0000 I NETWORK  [conn3] received client metadata from 172.18.1.1:58716 conn3: { driver: { name: "PyMongo", version: "3.6.1" }, os: { type: "Linux", name: "debian 8.10", architecture: "x86_64", version: "4.9.60-linuxkit-aufs" }, platform: "CPython 2.7.14.final.0" }
2018-05-07T14:12:59.736+0000 I NETWORK  [thread1] connection accepted from 172.18.1.1:58720 #4 (4 connections now open)
2018-05-07T14:12:59.736+0000 I NETWORK  [conn4] received client metadata from 172.18.1.1:58720 conn4: { driver: { name: "PyMongo", version: "3.6.1" }, os: { type: "Linux", name: "debian 8.10", architecture: "x86_64", version: "4.9.60-linuxkit-aufs" }, platform: "CPython 2.7.14.final.0" }
2018-05-07T14:12:59.745+0000 I ACCESS   [conn4] Successfully authenticated as principal penework on penework
2018-05-07T14:13:05.274+0000 I NETWORK  [thread1] connection accepted from 172.18.1.1:58722 #5 (5 connections now open)
2018-05-07T14:13:05.275+0000 I NETWORK  [thread1] connection accepted from 172.18.1.1:58724 #6 (6 connections now open)
2018-05-07T14:13:05.275+0000 I NETWORK  [conn5] received client metadata from 172.18.1.1:58722 conn5: { driver: { name: "PyMongo", version: "3.6.1" }, os: { type: "Darwin", name: "Darwin", architecture: "x86_64", version: "10.13.3" }, platform: "CPython 2.7.14.final.0" }
2018-05-07T14:13:05.276+0000 I NETWORK  [conn6] received client metadata from 172.18.1.1:58724 conn6: { driver: { name: "PyMongo", version: "3.6.1" }, os: { type: "Darwin", name: "Darwin", architecture: "x86_64", version: "10.13.3" }, platform: "CPython 2.7.14.final.0" }
