2018-04-22T09:58:21.833+0000 I CONTROL  [initandlisten] MongoDB starting : pid=8 port=27017 dbpath=/data/db 64-bit host=ecd024145ef9
2018-04-22T09:58:21.833+0000 I CONTROL  [initandlisten] db version v3.4.13
2018-04-22T09:58:21.833+0000 I CONTROL  [initandlisten] git version: fbdef2ccc53e0fcc9afb570063633d992b2aae42
2018-04-22T09:58:21.834+0000 I CONTROL  [initandlisten] OpenSSL version: OpenSSL 1.0.1t  3 May 2016
2018-04-22T09:58:21.834+0000 I CONTROL  [initandlisten] allocator: tcmalloc
2018-04-22T09:58:21.834+0000 I CONTROL  [initandlisten] modules: none
2018-04-22T09:58:21.834+0000 I CONTROL  [initandlisten] build environment:
2018-04-22T09:58:21.835+0000 I CONTROL  [initandlisten]     distmod: debian81
2018-04-22T09:58:21.835+0000 I CONTROL  [initandlisten]     distarch: x86_64
2018-04-22T09:58:21.835+0000 I CONTROL  [initandlisten]     target_arch: x86_64
2018-04-22T09:58:21.835+0000 I CONTROL  [initandlisten] options: { security: { authorization: "enabled" }, systemLog: { destination: "file", path: "/logs/mongodb.log" } }
2018-04-22T09:58:21.838+0000 W -        [initandlisten] Detected unclean shutdown - /data/db/mongod.lock is not empty.
2018-04-22T09:58:21.846+0000 I -        [initandlisten] Detected data files in /data/db created by the 'wiredTiger' storage engine, so setting the active storage engine to 'wiredTiger'.
2018-04-22T09:58:21.850+0000 W STORAGE  [initandlisten] Recovering data from the last clean checkpoint.
2018-04-22T09:58:21.851+0000 I STORAGE  [initandlisten] wiredtiger_open config: create,cache_size=487M,session_max=20000,eviction=(threads_min=4,threads_max=4),config_base=false,statistics=(fast),log=(enabled=true,archive=true,path=journal,compressor=snappy),file_manager=(close_idle_time=100000),checkpoint=(wait=60,log_size=2GB),statistics_log=(wait=0),verbose=(recovery_progress),
2018-04-22T09:58:22.651+0000 I STORAGE  [initandlisten] WiredTiger message [1524391102:651804][8:0x7ffff7feed40], txn-recover: Main recovery loop: starting at 4/13312
2018-04-22T09:58:22.674+0000 I STORAGE  [initandlisten] WiredTiger message [1524391102:674378][8:0x7ffff7feed40], txn-recover: Recovering log 4 through 5
2018-04-22T09:58:22.965+0000 I STORAGE  [initandlisten] WiredTiger message [1524391102:965559][8:0x7ffff7feed40], file:sizeStorer.wt, txn-recover: Recovering log 5 through 5
2018-04-22T09:58:23.055+0000 I CONTROL  [initandlisten] ** WARNING: You are running this process as the root user, which is not recommended.
2018-04-22T09:58:23.055+0000 I CONTROL  [initandlisten] 
2018-04-22T09:58:23.066+0000 I FTDC     [initandlisten] Initializing full-time diagnostic data capture with directory '/data/db/diagnostic.data'
2018-04-22T09:58:23.066+0000 I NETWORK  [thread1] waiting for connections on port 27017
2018-04-22T09:58:24.015+0000 I FTDC     [ftdc] Unclean full-time diagnostic data capture shutdown detected, found interim file, some metrics may have been lost. OK
2018-04-22T09:58:24.950+0000 I NETWORK  [thread1] connection accepted from 172.18.1.4:46748 #1 (1 connection now open)
2018-04-22T09:58:24.951+0000 I NETWORK  [conn1] received client metadata from 172.18.1.4:46748 conn1: { driver: { name: "PyMongo", version: "3.6.1" }, os: { type: "Linux", name: "debian 8.10", architecture: "x86_64", version: "4.9.60-linuxkit-aufs" }, platform: "CPython 2.7.14.final.0" }
2018-04-22T09:58:24.952+0000 I NETWORK  [thread1] connection accepted from 172.18.1.4:46750 #2 (2 connections now open)
2018-04-22T09:58:24.953+0000 I NETWORK  [conn2] received client metadata from 172.18.1.4:46750 conn2: { driver: { name: "PyMongo", version: "3.6.1" }, os: { type: "Linux", name: "debian 8.10", architecture: "x86_64", version: "4.9.60-linuxkit-aufs" }, platform: "CPython 2.7.14.final.0" }
2018-04-22T09:58:24.963+0000 I ACCESS   [conn2] Successfully authenticated as principal penework on penework
2018-04-22T09:58:24.986+0000 I NETWORK  [thread1] connection accepted from 172.18.1.4:46752 #3 (3 connections now open)
2018-04-22T09:58:24.987+0000 I NETWORK  [conn3] received client metadata from 172.18.1.4:46752 conn3: { driver: { name: "PyMongo", version: "3.6.1" }, os: { type: "Linux", name: "debian 8.10", architecture: "x86_64", version: "4.9.60-linuxkit-aufs" }, platform: "CPython 2.7.14.final.0" }
2018-04-22T09:58:26.065+0000 I NETWORK  [thread1] connection accepted from 172.18.1.1:40846 #4 (4 connections now open)
2018-04-22T09:58:26.066+0000 I NETWORK  [conn4] received client metadata from 172.18.1.1:40846 conn4: { driver: { name: "PyMongo", version: "3.6.1" }, os: { type: "Darwin", name: "Darwin", architecture: "x86_64", version: "10.13.3" }, platform: "CPython 2.7.14.final.0" }
2018-04-22T09:58:26.117+0000 I NETWORK  [thread1] connection accepted from 172.18.1.1:40848 #5 (5 connections now open)
2018-04-22T09:58:26.118+0000 I NETWORK  [conn5] received client metadata from 172.18.1.1:40848 conn5: { driver: { name: "PyMongo", version: "3.6.1" }, os: { type: "Darwin", name: "Darwin", architecture: "x86_64", version: "10.13.3" }, platform: "CPython 2.7.14.final.0" }
2018-04-22T09:58:26.213+0000 I NETWORK  [thread1] connection accepted from 172.18.1.1:40850 #6 (6 connections now open)
2018-04-22T09:58:26.214+0000 I NETWORK  [conn6] received client metadata from 172.18.1.1:40850 conn6: { driver: { name: "PyMongo", version: "3.6.1" }, os: { type: "Darwin", name: "Darwin", architecture: "x86_64", version: "10.13.3" }, platform: "CPython 2.7.14.final.0" }
2018-04-22T09:58:26.327+0000 I NETWORK  [thread1] connection accepted from 172.18.1.1:40852 #7 (7 connections now open)
2018-04-22T09:58:26.328+0000 I NETWORK  [thread1] connection accepted from 172.18.1.1:40854 #8 (8 connections now open)
2018-04-22T09:58:26.328+0000 I NETWORK  [conn7] received client metadata from 172.18.1.1:40852 conn7: { driver: { name: "PyMongo", version: "3.6.1" }, os: { type: "Darwin", name: "Darwin", architecture: "x86_64", version: "10.13.3" }, platform: "CPython 2.7.14.final.0" }
2018-04-22T09:58:26.329+0000 I NETWORK  [thread1] connection accepted from 172.18.1.1:40856 #9 (9 connections now open)
2018-04-22T09:58:26.329+0000 I NETWORK  [conn8] received client metadata from 172.18.1.1:40854 conn8: { driver: { name: "PyMongo", version: "3.6.1" }, os: { type: "Darwin", name: "Darwin", architecture: "x86_64", version: "10.13.3" }, platform: "CPython 2.7.14.final.0" }
2018-04-22T09:58:26.330+0000 I NETWORK  [conn9] received client metadata from 172.18.1.1:40856 conn9: { driver: { name: "PyMongo", version: "3.6.1" }, os: { type: "Darwin", name: "Darwin", architecture: "x86_64", version: "10.13.3" }, platform: "CPython 2.7.14.final.0" }
2018-04-22T09:58:28.870+0000 I NETWORK  [thread1] connection accepted from 172.18.1.4:46780 #10 (10 connections now open)
2018-04-22T09:58:28.871+0000 I NETWORK  [conn10] received client metadata from 172.18.1.4:46780 conn10: { driver: { name: "PyMongo", version: "3.6.1" }, os: { type: "Linux", name: "debian 8.10", architecture: "x86_64", version: "4.9.60-linuxkit-aufs" }, platform: "CPython 2.7.14.final.0" }
2018-04-22T09:58:28.883+0000 I ACCESS   [conn10] Successfully authenticated as principal penework on penework
