2018-04-22T10:07:57.898+0000 I CONTROL  [initandlisten] MongoDB starting : pid=8 port=27017 dbpath=/data/db 64-bit host=b6f094b66809
2018-04-22T10:07:57.898+0000 I CONTROL  [initandlisten] db version v3.4.13
2018-04-22T10:07:57.899+0000 I CONTROL  [initandlisten] git version: fbdef2ccc53e0fcc9afb570063633d992b2aae42
2018-04-22T10:07:57.899+0000 I CONTROL  [initandlisten] OpenSSL version: OpenSSL 1.0.1t  3 May 2016
2018-04-22T10:07:57.899+0000 I CONTROL  [initandlisten] allocator: tcmalloc
2018-04-22T10:07:57.899+0000 I CONTROL  [initandlisten] modules: none
2018-04-22T10:07:57.900+0000 I CONTROL  [initandlisten] build environment:
2018-04-22T10:07:57.900+0000 I CONTROL  [initandlisten]     distmod: debian81
2018-04-22T10:07:57.900+0000 I CONTROL  [initandlisten]     distarch: x86_64
2018-04-22T10:07:57.900+0000 I CONTROL  [initandlisten]     target_arch: x86_64
2018-04-22T10:07:57.900+0000 I CONTROL  [initandlisten] options: { security: { authorization: "enabled" }, systemLog: { destination: "file", path: "/logs/mongodb.log" } }
2018-04-22T10:07:57.902+0000 W -        [initandlisten] Detected unclean shutdown - /data/db/mongod.lock is not empty.
2018-04-22T10:07:57.907+0000 I -        [initandlisten] Detected data files in /data/db created by the 'wiredTiger' storage engine, so setting the active storage engine to 'wiredTiger'.
2018-04-22T10:07:57.909+0000 W STORAGE  [initandlisten] Recovering data from the last clean checkpoint.
2018-04-22T10:07:57.913+0000 I STORAGE  [initandlisten] wiredtiger_open config: create,cache_size=487M,session_max=20000,eviction=(threads_min=4,threads_max=4),config_base=false,statistics=(fast),log=(enabled=true,archive=true,path=journal,compressor=snappy),file_manager=(close_idle_time=100000),checkpoint=(wait=60,log_size=2GB),statistics_log=(wait=0),verbose=(recovery_progress),
2018-04-22T10:07:58.599+0000 I STORAGE  [initandlisten] WiredTiger message [1524391678:599342][8:0x7ffff7feed40], txn-recover: Main recovery loop: starting at 8/2816
2018-04-22T10:07:58.619+0000 I STORAGE  [initandlisten] WiredTiger message [1524391678:619275][8:0x7ffff7feed40], txn-recover: Recovering log 8 through 9
2018-04-22T10:07:58.896+0000 I STORAGE  [initandlisten] WiredTiger message [1524391678:896633][8:0x7ffff7feed40], file:sizeStorer.wt, txn-recover: Recovering log 9 through 9
2018-04-22T10:07:58.979+0000 I CONTROL  [initandlisten] ** WARNING: You are running this process as the root user, which is not recommended.
2018-04-22T10:07:58.979+0000 I CONTROL  [initandlisten] 
2018-04-22T10:07:58.986+0000 I FTDC     [initandlisten] Initializing full-time diagnostic data capture with directory '/data/db/diagnostic.data'
2018-04-22T10:07:58.987+0000 I NETWORK  [thread1] waiting for connections on port 27017
2018-04-22T10:07:59.011+0000 I FTDC     [ftdc] Unclean full-time diagnostic data capture shutdown detected, found interim file, some metrics may have been lost. OK
2018-04-22T10:08:00.085+0000 I NETWORK  [thread1] connection accepted from 172.18.1.1:40998 #1 (1 connection now open)
2018-04-22T10:08:00.086+0000 I NETWORK  [thread1] connection accepted from 172.18.1.1:41000 #2 (2 connections now open)
2018-04-22T10:08:00.086+0000 I NETWORK  [conn1] received client metadata from 172.18.1.1:40998 conn1: { driver: { name: "PyMongo", version: "3.6.1" }, os: { type: "Darwin", name: "Darwin", architecture: "x86_64", version: "10.13.3" }, platform: "CPython 2.7.14.final.0" }
2018-04-22T10:08:00.087+0000 I NETWORK  [conn2] received client metadata from 172.18.1.1:41000 conn2: { driver: { name: "PyMongo", version: "3.6.1" }, os: { type: "Darwin", name: "Darwin", architecture: "x86_64", version: "10.13.3" }, platform: "CPython 2.7.14.final.0" }
2018-04-22T10:08:00.247+0000 I NETWORK  [thread1] connection accepted from 172.18.1.1:41002 #3 (3 connections now open)
2018-04-22T10:08:00.247+0000 I NETWORK  [conn3] received client metadata from 172.18.1.1:41002 conn3: { driver: { name: "PyMongo", version: "3.6.1" }, os: { type: "Darwin", name: "Darwin", architecture: "x86_64", version: "10.13.3" }, platform: "CPython 2.7.14.final.0" }
2018-04-22T10:08:00.375+0000 I NETWORK  [thread1] connection accepted from 172.18.1.1:41004 #4 (4 connections now open)
2018-04-22T10:08:00.376+0000 I NETWORK  [conn4] received client metadata from 172.18.1.1:41004 conn4: { driver: { name: "PyMongo", version: "3.6.1" }, os: { type: "Darwin", name: "Darwin", architecture: "x86_64", version: "10.13.3" }, platform: "CPython 2.7.14.final.0" }
2018-04-22T10:08:00.467+0000 I NETWORK  [thread1] connection accepted from 172.18.1.1:41006 #5 (5 connections now open)
2018-04-22T10:08:00.468+0000 I NETWORK  [conn5] received client metadata from 172.18.1.1:41006 conn5: { driver: { name: "PyMongo", version: "3.6.1" }, os: { type: "Darwin", name: "Darwin", architecture: "x86_64", version: "10.13.3" }, platform: "CPython 2.7.14.final.0" }
2018-04-22T10:08:00.491+0000 I NETWORK  [thread1] connection accepted from 172.18.1.1:41008 #6 (6 connections now open)
2018-04-22T10:08:00.492+0000 I NETWORK  [conn6] received client metadata from 172.18.1.1:41008 conn6: { driver: { name: "PyMongo", version: "3.6.1" }, os: { type: "Darwin", name: "Darwin", architecture: "x86_64", version: "10.13.3" }, platform: "CPython 2.7.14.final.0" }
2018-04-22T10:08:02.516+0000 I NETWORK  [thread1] connection accepted from 172.18.1.4:46918 #7 (7 connections now open)
2018-04-22T10:08:02.516+0000 I NETWORK  [conn7] received client metadata from 172.18.1.4:46918 conn7: { driver: { name: "PyMongo", version: "3.6.1" }, os: { type: "Linux", name: "debian 8.10", architecture: "x86_64", version: "4.9.60-linuxkit-aufs" }, platform: "CPython 2.7.14.final.0" }
2018-04-22T10:08:02.518+0000 I NETWORK  [thread1] connection accepted from 172.18.1.4:46920 #8 (8 connections now open)
2018-04-22T10:08:02.519+0000 I NETWORK  [conn8] received client metadata from 172.18.1.4:46920 conn8: { driver: { name: "PyMongo", version: "3.6.1" }, os: { type: "Linux", name: "debian 8.10", architecture: "x86_64", version: "4.9.60-linuxkit-aufs" }, platform: "CPython 2.7.14.final.0" }
2018-04-22T10:08:02.528+0000 I ACCESS   [conn8] Successfully authenticated as principal penework on penework
2018-04-22T10:08:02.551+0000 I NETWORK  [thread1] connection accepted from 172.18.1.4:46922 #9 (9 connections now open)
2018-04-22T10:08:02.552+0000 I NETWORK  [conn9] received client metadata from 172.18.1.4:46922 conn9: { driver: { name: "PyMongo", version: "3.6.1" }, os: { type: "Linux", name: "debian 8.10", architecture: "x86_64", version: "4.9.60-linuxkit-aufs" }, platform: "CPython 2.7.14.final.0" }
2018-04-22T10:08:02.554+0000 I COMMAND  [conn8] CMD: drop penework.Projects
2018-04-22T10:08:28.967+0000 I NETWORK  [thread1] connection accepted from 172.18.1.4:46938 #10 (10 connections now open)
2018-04-22T10:08:28.968+0000 I NETWORK  [conn10] received client metadata from 172.18.1.4:46938 conn10: { driver: { name: "PyMongo", version: "3.6.1" }, os: { type: "Linux", name: "debian 8.10", architecture: "x86_64", version: "4.9.60-linuxkit-aufs" }, platform: "CPython 2.7.14.final.0" }
2018-04-22T10:08:28.978+0000 I ACCESS   [conn10] Successfully authenticated as principal penework on penework
2018-04-22T10:08:29.296+0000 I NETWORK  [thread1] connection accepted from 172.18.1.4:46940 #11 (11 connections now open)
2018-04-22T10:08:29.297+0000 I NETWORK  [conn11] received client metadata from 172.18.1.4:46940 conn11: { driver: { name: "PyMongo", version: "3.6.1" }, os: { type: "Linux", name: "debian 8.10", architecture: "x86_64", version: "4.9.60-linuxkit-aufs" }, platform: "CPython 2.7.14.final.0" }
2018-04-22T10:08:29.304+0000 I ACCESS   [conn11] Successfully authenticated as principal penework on penework
